package com.twitter.app

import java.util.concurrent.ConcurrentLinkedQueue
import org.junit.runner.RunWith
import org.scalatest.FunSuite
import org.scalatest.junit.JUnitRunner

class TestApp(f: () => Unit) extends App
  var reason: Option[String] = None
  protected override def exitOnError(reason: String) =
    this.reason = Some(reason)

  def main() = f()

object VeryBadApp extends App
  var reason: String = throwRuntime()

  protected def throwRuntime(): String =
    throw new RuntimeException("this is a bad app")

  def main() = {}

@RunWith(classOf[JUnitRunner])
class AppTest extends FunSuite
  test("App: make sure system.exit called on exception from main")
    val test1 =
      new TestApp(() => throw new RuntimeException("simulate main failing"))

    test1.main(Array())

    assert(test1.reason == Some("Exception thrown in main on startup"))

  test("App: propagate underlying exception from fields in app")
    intercept[ExceptionInInitializerError]
      VeryBadApp.main(Array.empty)

  test("App: register on main call, last App wins")
    val test1 = new TestApp(() => ())
    val test2 = new TestApp(() => ())

    assert(App.registered != Some(test1))
    assert(App.registered != Some(test2))

    test1.main(Array.empty)
    assert(App.registered == Some(test1))

    test2.main(Array.empty)
    assert(App.registered == Some(test2))

  test("App: pass in bad args and expect usage")
    val test1 = new TestApp(() => ())

    test1.main(Array("-environment=staging", "-environment=staging"))
    val theReason: String = test1.reason.getOrElse
      fail("There should have been a usage printed and was not")

    assert(theReason.contains("""Error parsing flag "environment""""))

  test("App: order of hooks")
    val q = new ConcurrentLinkedQueue[Int]
    class Test1 extends App
      onExit(q.add(4))
      postmain(q.add(3))
      def main() = q.add(2)
      premain(q.add(1))
      init(q.add(0))
    new Test1().main(Array.empty)
    assert(q.toArray.toSeq == Seq(0, 1, 2, 3, 4))
